Workbook

Sheet Read Me
B2: TCS — Five-Year Scenario Model (FY27–FY31)
B3: Prepared for the Chairman, Tata Sons · base year FY26 (year ended 31 March 2026)
B6: WHAT THIS IS | C6: A driver-based model of TCS revenue, margin, cash and dividend under four scenarios, and what each means for Tata Sons' parent-level funding capacity.
B7: HOW TO USE IT | C7: Every blue cell is an input you can change. Everything black is a formula. Change an assumption on 'Assumptions' and every sheet recalculates.
B9: COLOUR LEGEND
B10: Blue text | C10: Hard-coded input / scenario lever — edit these.
B11: Black text | C11: Formula — do not overwrite.
B12: Green text | C12: Link to another sheet in this workbook.
B13: Yellow fill | C13: Key judgement call. These drive the answer; challenge them first.
B15: SHEETS
B16: History | C16: TCS actuals FY22–FY26 and Q1 FY27, with sources.
B17: Assumptions | C17: All shared parameters, the revenue decomposition, and the four scenario driver blocks.
B18: Revenue Build | C18: Bucket-level revenue build for each scenario, FY27–FY31.
B19: Scenario Output | C19: Full P&L, cash, dividend and headcount output for each scenario.
B20: Tata Sons Bridge | C20: Parent-level cash bridge: TCS dividend vs. the capital call from Air India, Tata Electronics, Agratas and Tata Digital.
B21: Sensitivity | C21: FY31 dividend to Tata Sons across revenue CAGR × terminal operating margin.
B22: Risk Register | C22: Revenue-at-risk by exposure bucket.
B24: THE ONE CAVEAT | C24: TCS stopped disclosing a service-line revenue split after FY21. The seven-bucket decomposition on 'Assumptions' is a reconstruction, not a disclosure. It is the single most challengeable input in this model and the first thing to replace with internal MIS.
B26: PRIMARY SOURCES | C26: TCS Q4 FY26 Fact Sheet and press release; TCS Q1 FY27 press release; Tata Sons FY26 accounts as reported; Business Standard; Business Today; company filings.

Sheet History
A1: TCS — Reported actuals
A2: Source: TCS quarterly fact sheets and results press releases, tcs.com/investor-relations
A4: Metric | B4: FY22 | C4: FY23 | D4: FY24 | E4: FY25 | F4: FY26 | G4: Q1 FY27
A5: Revenue ($mn) | B5: 25707 | C5: 27927 | D5: 29080 | E5: 30180 | F5: 30017 | G5: 7624
A6: Revenue growth, reported USD | B6: 0.157 | C6: 0.086 | D6: 0.041 | E6: 0.038 | F6: -0.005
A7: Revenue growth, constant currency | B7: 0.157 | C7: 0.138 | D7: 0.034 | E7: 0.042 | F7: -0.024 | G7: 0.032
A8: Operating margin | B8: 0.25 | C8: 0.244 | D8: 0.246 | E8: 0.243 | F8: 0.25 | G8: 0.24
A9: Net margin | B9: 0.204 | C9: 0.192 | D9: 0.196 | E9: 0.19 | F9: 0.198 | G9: 0.192
A10: Net income ($mn) | B10: 5240 | C10: 5364 | D10: 5697 | E10: 5739 | F10: 5938 | G10: 1460
A11: Revenue (₹ crore) | B11: 191754 | C11: 225458 | D11: 240893 | E11: 255324 | F11: 267021
A12: Net income (₹ crore) | B12: 38449 | C12: 42303 | D12: 46099 | E12: 48797 | F12: 49454
A13: Order book / TCV ($bn) | B13: 34.6 | C13: 34.1 | D13: 42.7 | E13: 39.4 | F13: 40.7 | G13: 9.5
A14: Closing headcount | B14: 592195 | C14: 614795 | D14: 601546 | E14: 607979 | F14: 584519 | G14: 593798
A15: Dividend per share (₹) | B15: 43 | C15: 115 | D15: 73 | E15: 126 | F15: 110 | G15: 12
A16: Total shareholder payout (₹ crore) | B16: 15671 | C16: 42084 | D16: 26411 | E16: 44962 | F16: 39571
A18: Derived
A19: Revenue per employee ($) | B19: =B5*1000000/B14 -> 43409.688 | C19: =C5*1000000/C14 -> 45424.898 | D19: =D5*1000000/D14 -> 48342.105 | E19: =E5*1000000/E14 -> 49639.872 | F19: =F5*1000000/F14 -> 51353.335
A20: Implied ₹/US$ (revenue-weighted) | B20: =B11*10/B5 -> 74.592134 | C20: =C11*10/C5 -> 80.731192 | D20: =D11*10/D5 -> 82.838033 | E20: =E11*10/E5 -> 84.600398 | F20: =F11*10/F5 -> 88.956591
A21: Payout as % of net income | B21: =B16/B12 -> 0.40757887 | C21: =C16/C12 -> 0.99482306 | D21: =D16/D12 -> 0.57291915 | E21: =E16/E12 -> 0.9214091 | F21: =F16/F12 -> 0.80015772
A23: Note: FY26 was the first US-dollar revenue decline in TCS's listed history (-0.5% reported, -2.4% constant currency).

Sheet Assumptions
A1: Assumptions and scenario drivers
A2: Blue = input. Yellow = key judgement. Change these and the whole model moves.
A4: 1. Shared parameters
A5: FY26 revenue ($mn) [actual] | B5: 30017 | J5: TCS Q4 FY26 press release
A6: FY26 closing headcount [actual] | B6: 584519 | J6: TCS Q4 FY26 fact sheet
A7: FY26 revenue per employee ($) | B7: 51353 | J7: Derived
A8: FY26 implied ₹/US$ | B8: 88.96 | J8: ₹2,67,021 cr / $30,017mn
A9: ₹ depreciation p.a. | B9: 0.02 | J9: Long-run inflation differential
A10: Other income as % of revenue | B10: 0.016 | J10: Treasury income on ~₹50,000 cr cash
A11: Effective tax rate | B11: 0.255 | J11: FY26 effective rate
A12: Tata Sons stake in TCS | B12: 0.7174 | J12: 2,59,54,99,419 shares = 71.74%
A13: TCS shares outstanding (crore) | B13: 361.8 | J13: For DPS calculation
A15: 2. Revenue decomposition by AI exposure (FY26 base)
A16: Exposure bucket | B16: FY26 weight | C16: FY26 $mn | D16: Automatable share | E16: Gross rev at risk $mn | F16: Volume decay p.a.
A17: Application Development & Maintenance (custom) | B17: 0.32 | C17: =B17*$B$5 -> 9605.44 | D17: 0.55 | E17: =C17*D17 -> 5282.992 | F17: 1 | J17: Code generation, test automation and agentic L1/L2 support attack the core of this book. Largest single pool and the most exposed.
A18: Enterprise / Package Application Services | B18: 0.13 | C18: =B18*$B$5 -> 3902.21 | D18: 0.4 | E18: =C18*D18 -> 1560.884 | F18: 1 | J18: SAP/Oracle/Salesforce migration and rollout. Config work automates; change management, data migration and integration hold value.
A19: Cloud & Infrastructure Managed Services | B19: 0.16 | C19: =B19*$B$5 -> 4802.72 | D19: 0.5 | E19: =C19*D19 -> 2401.36 | F19: 1 | J19: AIOps compresses run-cost; offset by AI-infrastructure build, GPU estate operations and the HyperVault adjacency.
A20: Business Process Services | B20: 0.1 | C20: =B20*$B$5 -> 3001.7 | D20: 0.65 | E20: =C20*D20 -> 1951.105 | F20: 1 | J20: Most directly substitutable. Agentic workflows displace seat-based delivery; the FTE pricing model is the liability.
A21: Engineering & R&D Services | B21: 0.09 | C21: =B21*$B$5 -> 2701.53 | D21: 0.25 | E21: =C21*D21 -> 675.3825 | F21: 1 | J21: Embedded, semiconductor, automotive software. Least substitutable near-term and structurally growing.
A22: Consulting, Data, AI & Cybersecurity | B22: 0.15 | C22: =B22*$B$5 -> 4502.55 | D22: 0.15 | E22: =C22*D22 -> 675.3825 | F22: 0.88 | J22: The growth engine. AI-native demand, data estate rebuild, model governance, security. TCS AI book already ~8.5% of revenue.
A23: Products & Platforms (BaNCS, ignio, iON, ADD) | B23: 0.05 | C23: =B23*$B$5 -> 1500.85 | D23: 0.1 | E23: =C23*D23 -> 150.085 | F23: 0.92 | J23: IP-led, non-linear. AI raises product value rather than deflating it. Strategically under-scaled at ~5% of revenue.
A24: Total | B24: =SUM(B17:B23) -> 1 | C24: =SUM(C17:C23) -> 30017 | E24: =SUM(E17:E23) -> 12697.191
A25: TCS has not disclosed a service-line revenue split since FY21. Weights are a reconstruction from the last disclosure, deal mix and peer structure — replace with internal MIS.
A28: 3. Scenario drivers — Bull — AI Dividend | H28: Probability | I28: 0.15
A29: Per-bucket annual drivers | B29: Realisation deflation | C29: Volume growth
A30: Application Development & Maintenance (custom) | B30: -0.05 | C30: 0.09
A31: Enterprise / Package Application Services | B31: -0.03 | C31: 0.1
A32: Cloud & Infrastructure Managed Services | B32: -0.04 | C32: 0.12
A33: Business Process Services | B33: -0.06 | C33: 0.1
A34: Engineering & R&D Services | B34: -0.01 | C34: 0.12
A35: Consulting, Data, AI & Cybersecurity | B35: 0 | C35: 0.26
A36: Products & Platforms (BaNCS, ignio, iON, ADD) | B36: 0 | C36: 0.16
A37: Year-specific parameters | B37: FY27 | C37: FY28 | D37: FY29 | E37: FY30 | F37: FY31
A38: Deflation phasing multiplier | B38: 1 | C38: 1 | D38: 0.9 | E38: 0.9 | F38: 0.8
A39: Operating margin | B39: 0.245 | C39: 0.255 | D39: 0.262 | E39: 0.267 | F39: 0.27
A40: Free cash flow / net income | B40: 0.8 | C40: 0.75 | D40: 0.79 | E40: 0.84 | F40: 0.88
A41: Dividend as % of free cash flow | B41: 0.92 | C41: 0.92 | D41: 0.92 | E41: 0.92 | F41: 0.92
A42: Revenue per employee growth p.a. | B42: 0.055
A45: 3. Scenario drivers — Base — Managed Transition | H45: Probability | I45: 0.4
A46: Per-bucket annual drivers | B46: Realisation deflation | C46: Volume growth
...

Sheet Revenue Build
A1: Revenue build by exposure bucket ($mn)
A2: Each year = prior year × (1 + volume growth × decay^n) × (1 + deflation × phasing)
A4: Bull — AI Dividend
A5: Exposure bucket | B5: FY26 | C5: FY27 | D5: FY28 | E5: FY29 | F5: FY30 | G5: FY31
A6: Application Development & Maintenance (custom) | B6: =Assumptions!C17 -> 9605.44 | C6: =B6*(1+Assumptions!$C$30*Assumptions!$F$17^0)*(1+Assumptions!$B$30*Assumptions!B$38) -> 9946.4331 | D6: =C6*(1+Assumptions!$C$30*Assumptions!$F$17^1)*(1+Assumptions!$B$30*Assumptions!C$38) -> 10299.531 | E6: =D6*(1+Assumptions!$C$30*Assumptions!$F$17^2)*(1+Assumptions!$B$30*Assumptions!D$38) -> 10721.297 | F6: =E6*(1+Assumptions!$C$30*Assumptions!$F$17^3)*(1+Assumptions!$B$30*Assumptions!E$38) -> 11160.334 | G6: =F6*(1+Assumptions!$C$30*Assumptions!$F$17^4)*(1+Assumptions!$B$30*Assumptions!F$38) -> 11678.174
A7: Enterprise / Package Application Services | B7: =Assumptions!C18 -> 3902.21 | C7: =B7*(1+Assumptions!$C$31*Assumptions!$F$18^0)*(1+Assumptions!$B$31*Assumptions!B$38) -> 4163.6581 | D7: =C7*(1+Assumptions!$C$31*Assumptions!$F$18^1)*(1+Assumptions!$B$31*Assumptions!C$38) -> 4442.6232 | E7: =D7*(1+Assumptions!$C$31*Assumptions!$F$18^2)*(1+Assumptions!$B$31*Assumptions!D$38) -> 4754.9396 | F7: =E7*(1+Assumptions!$C$31*Assumptions!$F$18^3)*(1+Assumptions!$B$31*Assumptions!E$38) -> 5089.2118 | G7: =F7*(1+Assumptions!$C$31*Assumptions!$F$18^4)*(1+Assumptions!$B$31*Assumptions!F$38) -> 5463.7778
A8: Cloud & Infrastructure Managed Services | B8: =Assumptions!C19 -> 4802.72 | C8: =B8*(1+Assumptions!$C$32*Assumptions!$F$19^0)*(1+Assumptions!$B$32*Assumptions!B$38) -> 5163.8845 | D8: =C8*(1+Assumptions!$C$32*Assumptions!$F$19^1)*(1+Assumptions!$B$32*Assumptions!C$38) -> 5552.2087 | E8: =D8*(1+Assumptions!$C$32*Assumptions!$F$19^2)*(1+Assumptions!$B$32*Assumptions!D$38) -> 5994.6086 | F8: =E8*(1+Assumptions!$C$32*Assumptions!$F$19^3)*(1+Assumptions!$B$32*Assumptions!E$38) -> 6472.2591 | G8: =F8*(1+Assumptions!$C$32*Assumptions!$F$19^4)*(1+Assumptions!$B$32*Assumptions!F$38) -> 7016.9644
A9: Business Process Services | B9: =Assumptions!C20 -> 3001.7 | C9: =B9*(1+Assumptions!$C$33*Assumptions!$F$20^0)*(1+Assumptions!$B$33*Assumptions!B$38) -> 3103.7578 | D9: =C9*(1+Assumptions!$C$33*Assumptions!$F$20^1)*(1+Assumptions!$B$33*Assumptions!C$38) -> 3209.2856 | E9: =D9*(1+Assumptions!$C$33*Assumptions!$F$20^2)*(1+Assumptions!$B$33*Assumptions!D$38) -> 3339.5826 | F9: =E9*(1+Assumptions!$C$33*Assumptions!$F$20^3)*(1+Assumptions!$B$33*Assumptions!E$38) -> 3475.1696 | G9: =F9*(1+Assumptions!$C$33*Assumptions!$F$20^4)*(1+Assumptions!$B$33*Assumptions!F$38) -> 3639.1976
A10: Engineering & R&D Services | B10: =Assumptions!C21 -> 2701.53 | C10: =B10*(1+Assumptions!$C$34*Assumptions!$F$21^0)*(1+Assumptions!$B$34*Assumptions!B$38) -> 2995.4565 | D10: =C10*(1+Assumptions!$C$34*Assumptions!$F$21^1)*(1+Assumptions!$B$34*Assumptions!C$38) -> 3321.3621 | E10: =D10*(1+Assumptions!$C$34*Assumptions!$F$21^2)*(1+Assumptions!$B$34*Assumptions!D$38) -> 3686.4463 | F10: =E10*(1+Assumptions!$C$34*Assumptions!$F$21^3)*(1+Assumptions!$B$34*Assumptions!E$38) -> 4091.6604 | G10: =F10*(1+Assumptions!$C$34*Assumptions!$F$21^4)*(1+Assumptions!$B$34*Assumptions!F$38) -> 4545.9984
A11: Consulting, Data, AI & Cybersecurity | B11: =Assumptions!C22 -> 4502.55 | C11: =B11*(1+Assumptions!$C$35*Assumptions!$F$22^0)*(1+Assumptions!$B$35*Assumptions!B$38) -> 5673.213 | D11: =C11*(1+Assumptions!$C$35*Assumptions!$F$22^1)*(1+Assumptions!$B$35*Assumptions!C$38) -> 6971.2441 | E11: =D11*(1+Assumptions!$C$35*Assumptions!$F$22^2)*(1+Assumptions!$B$35*Assumptions!D$38) -> 8374.8623 | F11: =E11*(1+Assumptions!$C$35*Assumptions!$F$22^3)*(1+Assumptions!$B$35*Assumptions!E$38) -> 9858.7432 | G11: =F11*(1+Assumptions!$C$35*Assumptions!$F$22^4)*(1+Assumptions!$B$35*Assumptions!F$38) -> 11395.926
A12: Products & Platforms (BaNCS, ignio, iON, ADD) | B12: =Assumptions!C23 -> 1500.85 | C12: =B12*(1+Assumptions!$C$36*Assumptions!$F$23^0)*(1+Assumptions!$B$36*Assumptions!B$38) -> 1740.986 | D12: =C12*(1+Assumptions!$C$36*Assumptions!$F$23^1)*(1+Assumptions!$B$36*Assumptions!C$38) -> 1997.2591 | E12: =D12*(1+Assumptions!$C$36*Assumptions!$F$23^2)*(1+Assumptions!$B$36*Assumptions!D$38) -> 2267.736 | F12: =E12*(1+Assumptions!$C$36*Assumptions!$F$23^3)*(1+Assumptions!$B$36*Assumptions!E$38) -> 2550.2734 | G12: =F12*(1+Assumptions!$C$36*Assumptions!$F$23^4)*(1+Assumptions!$B$36*Assumptions!F$38) -> 2842.593
A13: Total revenue ($mn) | B13: =SUM(B6:B12) -> 30017 | C13: =SUM(C6:C12) -> 32787.389 | D13: =SUM(D6:D12) -> 35793.514 | E13: =SUM(E6:E12) -> 39139.473 | F13: =SUM(F6:F12) -> 42697.652 | G13: =SUM(G6:G12) -> 46582.631
A14: Growth, constant currency | C14: =C13/B13-1 -> 0.092294 | D14: =D13/C13-1 -> 0.091685413 | E14: =E13/D13-1 -> 0.093479458 | F14: =F13/E13-1 -> 0.090910252 | G14: =G13/F13-1 -> 0.090988131
A15: FY26–FY31 revenue CAGR | C15: =(G13/B13)^(1/5)-1 -> 0.091871038
A18: Base — Managed Transition
A19: Exposure bucket | B19: FY26 | C19: FY27 | D19: FY28 | E19: FY29 | F19: FY30 | G19: FY31
A20: Application Development & Maintenance (custom) | B20: =Assumptions!C17 -> 9605.44 | C20: =B20*(1+Assumptions!$C$47*Assumptions!$F$17^0)*(1+Assumptions!$B$47*Assumptions!B$55) -> 9570.8604 | D20: =C20*(1+Assumptions!$C$47*Assumptions!$F$17^1)*(1+Assumptions!$B$47*Assumptions!C$55) -> 9536.4053 | E20: =D20*(1+Assumptions!$C$47*Assumptions!$F$17^2)*(1+Assumptions!$B$47*Assumptions!D$55) -> 9502.0743 | F20: =E20*(1+Assumptions!$C$47*Assumptions!$F$17^3)*(1+Assumptions!$B$47*Assumptions!E$55) -> 9528.3 | G20: =F20*(1+Assumptions!$C$47*Assumptions!$F$17^4)*(1+Assumptions!$B$47*Assumptions!F$55) -> 9554.5981
A21: Enterprise / Package Application Services | B21: =Assumptions!C18 -> 3902.21 | C21: =B21*(1+Assumptions!$C$48*Assumptions!$F$18^0)*(1+Assumptions!$B$48*Assumptions!B$55) -> 4008.3501 | D21: =C21*(1+Assumptions!$C$48*Assumptions!$F$18^1)*(1+Assumptions!$B$48*Assumptions!C$55) -> 4117.3772 | E21: =D21*(1+Assumptions!$C$48*Assumptions!$F$18^2)*(1+Assumptions!$B$48*Assumptions!D$55) -> 4229.3699 | F21: =E21*(1+Assumptions!$C$48*Assumptions!$F$18^3)*(1+Assumptions!$B$48*Assumptions!E$55) -> 4362.5105 | G21: =F21*(1+Assumptions!$C$48*Assumptions!$F$18^4)*(1+Assumptions!$B$48*Assumptions!F$55) -> 4499.8423
A22: Cloud & Infrastructure Managed Services | B22: =Assumptions!C19 -> 4802.72 | C22: =B22*(1+Assumptions!$C$49*Assumptions!$F$19^0)*(1+Assumptions!$B$49*Assumptions!B$55) -> 4927.5907 | D22: =C22*(1+Assumptions!$C$49*Assumptions!$F$19^1)*(1+Assumptions!$B$49*Assumptions!C$55) -> 5055.7081 | E22: =D22*(1+Assumptions!$C$49*Assumptions!$F$19^2)*(1+Assumptions!$B$49*Assumptions!D$55) -> 5187.1565 | F22: =E22*(1+Assumptions!$C$49*Assumptions!$F$19^3)*(1+Assumptions!$B$49*Assumptions!E$55) -> 5350.0332 | G22: =F22*(1+Assumptions!$C$49*Assumptions!$F$19^4)*(1+Assumptions!$B$49*Assumptions!F$55) -> 5518.0242
A23: Business Process Services | B23: =Assumptions!C20 -> 3001.7 | C23: =B23*(1+Assumptions!$C$50*Assumptions!$F$20^0)*(1+Assumptions!$B$50*Assumptions!B$55) -> 2927.2578 | D23: =C23*(1+Assumptions!$C$50*Assumptions!$F$20^1)*(1+Assumptions!$B$50*Assumptions!C$55) -> 2854.6618 | E23: =D23*(1+Assumptions!$C$50*Assumptions!$F$20^2)*(1+Assumptions!$B$50*Assumptions!D$55) -> 2783.8662 | F23: =E23*(1+Assumptions!$C$50*Assumptions!$F$20^3)*(1+Assumptions!$B$50*Assumptions!E$55) -> 2738.4335 | G23: =F23*(1+Assumptions!$C$50*Assumptions!$F$20^4)*(1+Assumptions!$B$50*Assumptions!F$55) -> 2693.7423
A24: Engineering & R&D Services | B24: =Assumptions!C21 -> 2701.53 | C24: =B24*(1+Assumptions!$C$51*Assumptions!$F$21^0)*(1+Assumptions!$B$51*Assumptions!B$55) -> 2859.2994 | D24: =C24*(1+Assumptions!$C$51*Assumptions!$F$21^1)*(1+Assumptions!$B$51*Assumptions!C$55) -> 3026.2824 | E24: =D24*(1+Assumptions!$C$51*Assumptions!$F$21^2)*(1+Assumptions!$B$51*Assumptions!D$55) -> 3203.0173 | F24: =E24*(1+Assumptions!$C$51*Assumptions!$F$21^3)*(1+Assumptions!$B$51*Assumptions!E$55) -> 3396.9921 | G24: =F24*(1+Assumptions!$C$51*Assumptions!$F$21^4)*(1+Assumptions!$B$51*Assumptions!F$55) -> 3602.7139
A25: Consulting, Data, AI & Cybersecurity | B25: =Assumptions!C22 -> 4502.55 | C25: =B25*(1+Assumptions!$C$52*Assumptions!$F$22^0)*(1+Assumptions!$B$52*Assumptions!B$55) -> 5206.7488 | D25: =C25*(1+Assumptions!$C$52*Assumptions!$F$22^1)*(1+Assumptions!$B$52*Assumptions!C$55) -> 5910.8679 | E25: =D25*(1+Assumptions!$C$52*Assumptions!$F$22^2)*(1+Assumptions!$B$52*Assumptions!D$55) -> 6600.0997 | F25: =E25*(1+Assumptions!$C$52*Assumptions!$F$22^3)*(1+Assumptions!$B$52*Assumptions!E$55) -> 7276.326 | G25: =F25*(1+Assumptions!$C$52*Assumptions!$F$22^4)*(1+Assumptions!$B$52*Assumptions!F$55) -> 7916.6584
A26: Products & Platforms (BaNCS, ignio, iON, ADD) | B26: =Assumptions!C23 -> 1500.85 | C26: =B26*(1+Assumptions!$C$53*Assumptions!$F$23^0)*(1+Assumptions!$B$53*Assumptions!B$55) -> 1649.2841 | D26: =C26*(1+Assumptions!$C$53*Assumptions!$F$23^1)*(1+Assumptions!$B$53*Assumptions!C$55) -> 1798.0297 | E26: =D26*(1+Assumptions!$C$53*Assumptions!$F$23^2)*(1+Assumptions!$B$53*Assumptions!D$55) -> 1945.7791 | F26: =E26*(1+Assumptions!$C$53*Assumptions!$F$23^3)*(1+Assumptions!$B$53*Assumptions!E$55) -> 2093.4341 | G26: =F26*(1+Assumptions!$C$53*Assumptions!$F$23^4)*(1+Assumptions!$B$53*Assumptions!F$55) -> 2238.0779
A27: Total revenue ($mn) | B27: =SUM(B20:B26) -> 30017 | C27: =SUM(C20:C26) -> 31149.391 | D27: =SUM(D20:D26) -> 32299.332 | E27: =SUM(E20:E26) -> 33451.363 | F27: =SUM(F20:F26) -> 34746.029 | G27: =SUM(G20:G26) -> 36023.657
A28: Growth, constant currency | C28: =C27/B27-1 -> 0.037725 | D28: =D27/C27-1 -> 0.03691697 | E28: =E27/D27-1 -> 0.035667316 | F28: =F27/E27-1 -> 0.038702949 | G28: =G27/F27-1 -> 0.036770465
A29: FY26–FY31 revenue CAGR | C29: =(G27/B27)^(1/5)-1 -> 0.037156045
A32: Bear — Slow Bleed
A33: Exposure bucket | B33: FY26 | C33: FY27 | D33: FY28 | E33: FY29 | F33: FY30 | G33: FY31
A34: Application Development & Maintenance (custom) | B34: =Assumptions!C17 -> 9605.44 | C34: =B34*(1+Assumptions!$C$64*Assumptions!$F$17^0)*(1+Assumptions!$B$64*Assumptions!B$72) -> 9092.1253 | D34: =C34*(1+Assumptions!$C$64*Assumptions!$F$17^1)*(1+Assumptions!$B$64*Assumptions!C$72) -> 8439.3107 | E34: =D34*(1+Assumptions!$C$64*Assumptions!$F$17^2)*(1+Assumptions!$B$64*Assumptions!D$72) -> 7755.8953 | F34: =E34*(1+Assumptions!$C$64*Assumptions!$F$17^3)*(1+Assumptions!$B$64*Assumptions!E$72) -> 7199.022 | G34: =F34*(1+Assumptions!$C$64*Assumptions!$F$17^4)*(1+Assumptions!$B$64*Assumptions!F$72) -> 6748.2193
A35: Enterprise / Package Application Services | B35: =Assumptions!C18 -> 3902.21 | C35: =B35*(1+Assumptions!$C$65*Assumptions!$F$18^0)*(1+Assumptions!$B$65*Assumptions!B$72) -> 3826.351 | D35: =C35*(1+Assumptions!$C$65*Assumptions!$F$18^1)*(1+Assumptions!$B$65*Assumptions!C$72) -> 3704.6731 | E35: =D35*(1+Assumptions!$C$65*Assumptions!$F$18^2)*(1+Assumptions!$B$65*Assumptions!D$72) -> 3563.9696 | F35: =E35*(1+Assumptions!$C$65*Assumptions!$F$18^3)*(1+Assumptions!$B$65*Assumptions!E$72) -> 3450.6354 | G35: =F35*(1+Assumptions!$C$65*Assumptions!$F$18^4)*(1+Assumptions!$B$65*Assumptions!F$72) -> 3362.2301
A36: Cloud & Infrastructure Managed Services | B36: =Assumptions!C19 -> 4802.72 | C36: =B36*(1+Assumptions!$C$66*Assumptions!$F$19^0)*(1+Assumptions!$B$66*Assumptions!B$72) -> 4675.1598 | D36: =C36*(1+Assumptions!$C$66*Assumptions!$F$19^1)*(1+Assumptions!$B$66*Assumptions!C$72) -> 4473.1929 | E36: =D36*(1+Assumptions!$C$66*Assumptions!$F$19^2)*(1+Assumptions!$B$66*Assumptions!D$72) -> 4242.734 | F36: =E36*(1+Assumptions!$C$66*Assumptions!$F$19^3)*(1+Assumptions!$B$66*Assumptions!E$72) -> 4059.4479 | G36: =F36*(1+Assumptions!$C$66*Assumptions!$F$19^4)*(1+Assumptions!$B$66*Assumptions!F$72) -> 3917.8543
A37: Business Process Services | B37: =Assumptions!C20 -> 3001.7 | C37: =B37*(1+Assumptions!$C$67*Assumptions!$F$20^0)*(1+Assumptions!$B$67*Assumptions!B$72) -> 2767.8075 | D37: =C37*(1+Assumptions!$C$67*Assumptions!$F$20^1)*(1+Assumptions!$B$67*Assumptions!C$72) -> 2484.384 | E37: =D37*(1+Assumptions!$C$67*Assumptions!$F$20^2)*(1+Assumptions!$B$67*Assumptions!D$72) -> 2199.5743 | F37: =E37*(1+Assumptions!$C$67*Assumptions!$F$20^3)*(1+Assumptions!$B$67*Assumptions!E$72) -> 1974.3379 | G37: =F37*(1+Assumptions!$C$67*Assumptions!$F$20^4)*(1+Assumptions!$B$67*Assumptions!F$72) -> 1796.3316
A38: Engineering & R&D Services | B38: =Assumptions!C21 -> 2701.53 | C38: =B38*(1+Assumptions!$C$68*Assumptions!$F$21^0)*(1+Assumptions!$B$68*Assumptions!B$72) -> 2719.6843 | D38: =C38*(1+Assumptions!$C$68*Assumptions!$F$21^1)*(1+Assumptions!$B$68*Assumptions!C$72) -> 2715.3328 | E38: =D38*(1+Assumptions!$C$68*Assumptions!$F$21^2)*(1+Assumptions!$B$68*Assumptions!D$72) -> 2699.6925 | F38: =E38*(1+Assumptions!$C$68*Assumptions!$F$21^3)*(1+Assumptions!$B$68*Assumptions!E$72) -> 2695.373 | G38: =F38*(1+Assumptions!$C$68*Assumptions!$F$21^4)*(1+Assumptions!$B$68*Assumptions!F$72) -> 2702.2731
A39: Consulting, Data, AI & Cybersecurity | B39: =Assumptions!C22 -> 4502.55 | C39: =B39*(1+Assumptions!$C$69*Assumptions!$F$22^0)*(1+Assumptions!$B$69*Assumptions!B$72) -> 4837.8999 | D39: =C39*(1+Assumptions!$C$69*Assumptions!$F$22^1)*(1+Assumptions!$B$69*Assumptions!C$72) -> 5093.9603 | E39: =D39*(1+Assumptions!$C$69*Assumptions!$F$22^2)*(1+Assumptions!$B$69*Assumptions!D$72) -> 5284.6573 | F39: =E39*(1+Assumptions!$C$69*Assumptions!$F$22^3)*(1+Assumptions!$B$69*Assumptions!E$72) -> 5453.5731 | G39: =F39*(1+Assumptions!$C$69*Assumptions!$F$22^4)*(1+Assumptions!$B$69*Assumptions!F$72) -> 5604.0465
A40: Products & Platforms (BaNCS, ignio, iON, ADD) | B40: =Assumptions!C23 -> 1500.85 | C40: =B40*(1+Assumptions!$C$70*Assumptions!$F$23^0)*(1+Assumptions!$B$70*Assumptions!B$72) -> 1552.7194 | D40: =C40*(1+Assumptions!$C$70*Assumptions!$F$23^1)*(1+Assumptions!$B$70*Assumptions!C$72) -> 1589.2766 | E40: =D40*(1+Assumptions!$C$70*Assumptions!$F$23^2)*(1+Assumptions!$B$70*Assumptions!D$72) -> 1614.8769 | F40: =E40*(1+Assumptions!$C$70*Assumptions!$F$23^3)*(1+Assumptions!$B$70*Assumptions!E$72) -> 1639.6162 | G40: =F40*(1+Assumptions!$C$70*Assumptions!$F$23^4)*(1+Assumptions!$B$70*Assumptions!F$72) -> 1663.9203
A41: Total revenue ($mn) | B41: =SUM(B34:B40) -> 30017 | C41: =SUM(C34:C40) -> 29471.747 | D41: =SUM(D34:D40) -> 28500.13 | E41: =SUM(E34:E40) -> 27361.4 | F41: =SUM(F34:F40) -> 26472.005 | G41: =SUM(G34:G40) -> 25794.875
A42: Growth, constant currency | C42: =C41/B41-1 -> -0.0181648 | D42: =D41/C41-1 -> -0.032967738 | E42: =E41/D41-1 -> -0.039955276 | F42: =F41/E41-1 -> -0.032505441 | G42: =G41/F41-1 -> -0.02557911
A43: FY26–FY31 revenue CAGR | C43: =(G41/B41)^(1/5)-1 -> -0.029862642
A46: Severe — Structural Break
A47: Exposure bucket | B47: FY26 | C47: FY27 | D47: FY28 | E47: FY29 | F47: FY30 | G47: FY31
...

Sheet Scenario Output
A1: Scenario output — P&L, cash, dividend and headcount
A2: FY26 column is actual. FY27–FY31 are model output.
A4: Bull — AI Dividend
B5: FY26A | C5: FY27 | D5: FY28 | E5: FY29 | F5: FY30 | G5: FY31
A6: Revenue ($mn) | B6: 30017 | C6: ='Revenue Build'!C13 -> 32787.389 | D6: ='Revenue Build'!D13 -> 35793.514 | E6: ='Revenue Build'!E13 -> 39139.473 | F6: ='Revenue Build'!F13 -> 42697.652 | G6: ='Revenue Build'!G13 -> 46582.631
A7: growth, constant currency | C7: =C6/B6-1 -> 0.092294 | D7: =D6/C6-1 -> 0.091685413 | E7: =E6/D6-1 -> 0.093479458 | F7: =F6/E6-1 -> 0.090910252 | G7: =G6/F6-1 -> 0.090988131
A8: Operating margin | B8: 0.25 | C8: =Assumptions!B39 -> 0.245 | D8: =Assumptions!C39 -> 0.255 | E8: =Assumptions!D39 -> 0.262 | F8: =Assumptions!E39 -> 0.267 | G8: =Assumptions!F39 -> 0.27
A9: Operating income ($mn) | B9: =B6*B8 -> 7504.25 | C9: =C6*C8 -> 8032.9103 | D9: =D6*D8 -> 9127.3461 | E9: =E6*E8 -> 10254.542 | F9: =F6*F8 -> 11400.273 | G9: =G6*G8 -> 12577.31
A10: Profit before tax ($mn) | C10: =C6*(C8+Assumptions!$B$10) -> 8557.5085 | D10: =D6*(D8+Assumptions!$B$10) -> 9700.0424 | E10: =E6*(E8+Assumptions!$B$10) -> 10880.773 | F10: =F6*(F8+Assumptions!$B$10) -> 12083.435 | G10: =G6*(G8+Assumptions!$B$10) -> 13322.633
A11: Net income ($mn) | B11: 5938 | C11: =C10*(1-Assumptions!$B$11) -> 6375.3439 | D11: =D10*(1-Assumptions!$B$11) -> 7226.5316 | E11: =E10*(1-Assumptions!$B$11) -> 8106.1762 | F11: =F10*(1-Assumptions!$B$11) -> 9002.1594 | G11: =G10*(1-Assumptions!$B$11) -> 9925.3613
A12: net margin | B12: 0.198 | C12: =C11/C6 -> 0.194445 | D12: =D11/D6 -> 0.201895 | E12: =E11/E6 -> 0.20711 | F12: =F11/F6 -> 0.210835 | G12: =G11/G6 -> 0.21307
A13: ₹ / US$ | B13: 88.956591 | C13: =B13*(1+Assumptions!$B$9) -> 90.735723 | D13: =C13*(1+Assumptions!$B$9) -> 92.550438 | E13: =D13*(1+Assumptions!$B$9) -> 94.401446 | F13: =E13*(1+Assumptions!$B$9) -> 96.289475 | G13: =F13*(1+Assumptions!$B$9) -> 98.215265
A14: Revenue (₹ crore) | B14: 267021 | C14: =C6*C13/10 -> 297498.74 | D14: =D6*D13/10 -> 331270.54 | E14: =E6*E13/10 -> 369482.28 | F14: =F6*F13/10 -> 411133.45 | G14: =G6*G13/10 -> 457512.55
A15: Net income (₹ crore) | B15: 49454 | C15: =C11*C13/10 -> 57847.143 | D15: =D11*D13/10 -> 66881.866 | E15: =E11*E13/10 -> 76523.475 | F15: =F11*F13/10 -> 86681.321 | G15: =G11*G13/10 -> 97482.199
A16: Free cash flow (₹ crore) | B16: 42983 | C16: =C15*Assumptions!B40 -> 46277.715 | D16: =D15*Assumptions!C40 -> 50161.399 | E16: =E15*Assumptions!D40 -> 60453.546 | F16: =F15*Assumptions!E40 -> 72812.31 | G16: =G15*Assumptions!F40 -> 85784.335
A17: Total dividend (₹ crore) | B17: 39571 | C17: =C16*Assumptions!B41 -> 42575.498 | D17: =D16*Assumptions!C41 -> 46148.487 | E17: =E16*Assumptions!D41 -> 55617.262 | F17: =F16*Assumptions!E41 -> 66987.325 | G17: =G16*Assumptions!F41 -> 78921.588
A18: Dividend per share (₹) | B18: 110 | C18: =C17/Assumptions!$B$13 -> 117.67689 | D18: =D17/Assumptions!$B$13 -> 127.55248 | E18: =E17/Assumptions!$B$13 -> 153.72378 | F18: =F17/Assumptions!$B$13 -> 185.15015 | G18: =G17/Assumptions!$B$13 -> 218.13595
A19: Dividend to Tata Sons (₹ crore) | B19: 28291 | C19: =C17*Assumptions!$B$12 -> 30543.662 | D19: =D17*Assumptions!$B$12 -> 33106.925 | E19: =E17*Assumptions!$B$12 -> 39899.824 | F19: =F17*Assumptions!$B$12 -> 48056.707 | G19: =G17*Assumptions!$B$12 -> 56618.347
A20: Revenue per employee ($) | B20: 51353 | C20: =B20*(1+Assumptions!$B$42) -> 54177.415 | D20: =C20*(1+Assumptions!$B$42) -> 57157.173 | E20: =D20*(1+Assumptions!$B$42) -> 60300.817 | F20: =E20*(1+Assumptions!$B$42) -> 63617.362 | G20: =F20*(1+Assumptions!$B$42) -> 67116.317
A21: Closing headcount | B21: 584519 | C21: =C6*1000000/C20 -> 605185.56 | D21: =D6*1000000/D20 -> 626229.61 | E21: =E6*1000000/E20 -> 649070.35 | F21: =F6*1000000/F20 -> 671163.51 | G21: =G6*1000000/G20 -> 694058.22
A22: change vs FY26 | C22: =C21-$B$21 -> 20666.556 | D22: =D21-$B$21 -> 41710.614 | E22: =E21-$B$21 -> 64551.35 | F22: =F21-$B$21 -> 86644.506 | G22: =G21-$B$21 -> 109539.22
A24: FY26–FY31 revenue CAGR | C24: =(G6/B6)^(1/5)-1 -> 0.091871038
A25: Cumulative dividend to Tata Sons, FY27–FY31 (₹ crore) | C25: =SUM(C19:G19) -> 208225.46
A28: Base — Managed Transition
B29: FY26A | C29: FY27 | D29: FY28 | E29: FY29 | F29: FY30 | G29: FY31
A30: Revenue ($mn) | B30: 30017 | C30: ='Revenue Build'!C27 -> 31149.391 | D30: ='Revenue Build'!D27 -> 32299.332 | E30: ='Revenue Build'!E27 -> 33451.363 | F30: ='Revenue Build'!F27 -> 34746.029 | G30: ='Revenue Build'!G27 -> 36023.657
A31: growth, constant currency | C31: =C30/B30-1 -> 0.037725 | D31: =D30/C30-1 -> 0.03691697 | E31: =E30/D30-1 -> 0.035667316 | F31: =F30/E30-1 -> 0.038702949 | G31: =G30/F30-1 -> 0.036770465
A32: Operating margin | B32: 0.25 | C32: =Assumptions!B56 -> 0.243 | D32: =Assumptions!C56 -> 0.246 | E32: =Assumptions!D56 -> 0.25 | F32: =Assumptions!E56 -> 0.252 | G32: =Assumptions!F56 -> 0.255
A33: Operating income ($mn) | B33: =B30*B32 -> 7504.25 | C33: =C30*C32 -> 7569.3021 | D33: =D30*D32 -> 7945.6358 | E33: =E30*E32 -> 8362.8407 | F33: =F30*F32 -> 8755.9994 | G33: =G30*G32 -> 9186.0325
A34: Profit before tax ($mn) | C34: =C30*(C32+Assumptions!$B$10) -> 8067.6924 | D34: =D30*(D32+Assumptions!$B$10) -> 8462.4251 | E34: =E30*(E32+Assumptions!$B$10) -> 8898.0626 | F34: =F30*(F32+Assumptions!$B$10) -> 9311.9359 | G34: =G30*(G32+Assumptions!$B$10) -> 9762.4111
A35: Net income ($mn) | B35: 5938 | C35: =C34*(1-Assumptions!$B$11) -> 6010.4308 | D35: =D34*(1-Assumptions!$B$11) -> 6304.5067 | E35: =E34*(1-Assumptions!$B$11) -> 6629.0566 | F35: =F34*(1-Assumptions!$B$11) -> 6937.3922 | G35: =G34*(1-Assumptions!$B$11) -> 7272.9962
A36: net margin | B36: 0.198 | C36: =C35/C30 -> 0.192955 | D36: =D35/D30 -> 0.19519 | E36: =E35/E30 -> 0.19817 | F36: =F35/F30 -> 0.19966 | G36: =G35/G30 -> 0.201895
A37: ₹ / US$ | B37: 88.956591 | C37: =B37*(1+Assumptions!$B$9) -> 90.735723 | D37: =C37*(1+Assumptions!$B$9) -> 92.550438 | E37: =D37*(1+Assumptions!$B$9) -> 94.401446 | F37: =E37*(1+Assumptions!$B$9) -> 96.289475 | G37: =F37*(1+Assumptions!$B$9) -> 98.215265
A38: Revenue (₹ crore) | B38: 267021 | C38: =C30*C37/10 -> 282636.25 | D38: =D30*D37/10 -> 298931.74 | E38: =E30*E37/10 -> 315785.7 | F38: =F30*F37/10 -> 334567.69 | G38: =G30*G37/10 -> 353807.3
A39: Net income (₹ crore) | B39: 49454 | C39: =C35*C37/10 -> 54536.079 | D39: =D35*D37/10 -> 58348.485 | E39: =E35*E37/10 -> 62579.253 | F39: =F35*F37/10 -> 66799.786 | G39: =G35*G37/10 -> 71431.925
A40: Free cash flow (₹ crore) | B40: 42983 | C40: =C39*Assumptions!B57 -> 43628.863 | D40: =D39*Assumptions!C57 -> 44344.849 | E40: =E39*Assumptions!D57 -> 48811.817 | F40: =F39*Assumptions!E57 -> 54775.824 | G40: =G39*Assumptions!F57 -> 60717.136
A41: Total dividend (₹ crore) | B41: 39571 | C41: =C40*Assumptions!B58 -> 40574.842 | D41: =D40*Assumptions!C58 -> 41240.71 | E41: =E40*Assumptions!D58 -> 44906.872 | F41: =F40*Assumptions!E58 -> 50393.758 | G41: =G40*Assumptions!F58 -> 55859.765
A42: Dividend per share (₹) | B42: 110 | C42: =C41/Assumptions!$B$13 -> 112.14716 | D42: =D41/Assumptions!$B$13 -> 113.98759 | E42: =E41/Assumptions!$B$13 -> 124.12071 | F42: =F41/Assumptions!$B$13 -> 139.28623 | G42: =G41/Assumptions!$B$13 -> 154.39404
A43: Dividend to Tata Sons (₹ crore) | B43: 28291 | C43: =C41*Assumptions!$B$12 -> 29108.392 | D43: =D41*Assumptions!$B$12 -> 29586.085 | E43: =E41*Assumptions!$B$12 -> 32216.19 | F43: =F41*Assumptions!$B$12 -> 36152.482 | G43: =G41*Assumptions!$B$12 -> 40073.796
A44: Revenue per employee ($) | B44: 51353 | C44: =B44*(1+Assumptions!$B$59) -> 53407.12 | D44: =C44*(1+Assumptions!$B$59) -> 55543.405 | E44: =D44*(1+Assumptions!$B$59) -> 57765.141 | F44: =E44*(1+Assumptions!$B$59) -> 60075.747 | G44: =F44*(1+Assumptions!$B$59) -> 62478.776
...

Sheet Tata Sons Bridge
A1: Tata Sons — parent-level cash bridge (₹ crore)
A2: Does the TCS dividend still fund the group's strategic bets? Capital deployment is held constant across scenarios: the commitments do not shrink because TCS slows.
A4: Bull — AI Dividend
B5: FY26A | C5: FY27 | D5: FY28 | E5: FY29 | F5: FY30 | G5: FY31
A6: Dividend from TCS | B6: 28291 | C6: ='Scenario Output'!C19 -> 30543.662 | D6: ='Scenario Output'!D19 -> 33106.925 | E6: ='Scenario Output'!E19 -> 39899.824 | F6: ='Scenario Output'!F19 -> 48056.707 | G6: ='Scenario Output'!G19 -> 56618.347
A7: Dividend from other listed holdings | B7: 4237 | C7: =B7*(1+Assumptions!$B$98) -> 4618.33 | D7: =C7*(1+Assumptions!$B$98) -> 5033.9797 | E7: =D7*(1+Assumptions!$B$98) -> 5487.0379 | F7: =E7*(1+Assumptions!$B$98) -> 5980.8713 | G7: =F7*(1+Assumptions!$B$98) -> 6519.1497
A8: Total dividend inflow | B8: =B6+B7 -> 32528 | C8: =C6+C7 -> 35161.992 | D8: =D6+D7 -> 38140.905 | E8: =E6+E7 -> 45386.862 | F8: =F6+F7 -> 54037.578 | G8: =G6+G7 -> 63137.497
A9: Parent opex, interest and tax | B9: 6984 | C9: =B9*(1+Assumptions!$B$100) -> 7403.04 | D9: =C9*(1+Assumptions!$B$100) -> 7847.2224 | E9: =D9*(1+Assumptions!$B$100) -> 8318.0557 | F9: =E9*(1+Assumptions!$B$100) -> 8817.1391 | G9: =F9*(1+Assumptions!$B$100) -> 9346.1674
A10: Equity deployment into strategic bets | B10: 15956 | C10: =Assumptions!B104 -> 20000 | D10: =Assumptions!C104 -> 24000 | E10: =Assumptions!D104 -> 26000 | F10: =Assumptions!E104 -> 27000 | G10: =Assumptions!F104 -> 28000
A11: Surplus / (deficit) | B11: =B8-B9-B10 -> 9588 | C11: =C8-C9-C10 -> 7758.952 | D11: =D8-D9-D10 -> 6293.6822 | E11: =E8-E9-E10 -> 11068.806 | F11: =F8-F9-F10 -> 18220.439 | G11: =G8-G9-G10 -> 25791.329
A12: Cumulative net cash | B12: 21841 | C12: =B12+C11 -> 29599.952 | D12: =C12+D11 -> 35893.634 | E12: =D12+E11 -> 46962.44 | F12: =E12+F11 -> 65182.879 | G12: =F12+G11 -> 90974.208
A13: TCS as % of dividend inflow | B13: =B6/B8 -> 0.86974299 | C13: =C6/C8 -> 0.86865562 | D13: =D6/D8 -> 0.86801625 | E13: =E6/E8 -> 0.87910515 | F13: =F6/F8 -> 0.88932015 | G13: =G6/G8 -> 0.89674678
A14: Dividend cover of capital call (×) | B14: =B8/B10 -> 2.0386062 | C14: =C8/C10 -> 1.7580996 | D14: =D8/D10 -> 1.5892044 | E14: =E8/E10 -> 1.7456485 | F14: =F8/F10 -> 2.0013918 | G14: =G8/G10 -> 2.2549106
A16: Cumulative surplus / (deficit) FY27–FY31 | C16: =SUM(C11:G11) -> 69133.208
A19: Base — Managed Transition
B20: FY26A | C20: FY27 | D20: FY28 | E20: FY29 | F20: FY30 | G20: FY31
A21: Dividend from TCS | B21: 28291 | C21: ='Scenario Output'!C43 -> 29108.392 | D21: ='Scenario Output'!D43 -> 29586.085 | E21: ='Scenario Output'!E43 -> 32216.19 | F21: ='Scenario Output'!F43 -> 36152.482 | G21: ='Scenario Output'!G43 -> 40073.796
A22: Dividend from other listed holdings | B22: 4237 | C22: =B22*(1+Assumptions!$B$98) -> 4618.33 | D22: =C22*(1+Assumptions!$B$98) -> 5033.9797 | E22: =D22*(1+Assumptions!$B$98) -> 5487.0379 | F22: =E22*(1+Assumptions!$B$98) -> 5980.8713 | G22: =F22*(1+Assumptions!$B$98) -> 6519.1497
A23: Total dividend inflow | B23: =B21+B22 -> 32528 | C23: =C21+C22 -> 33726.722 | D23: =D21+D22 -> 34620.065 | E23: =E21+E22 -> 37703.228 | F23: =F21+F22 -> 42133.354 | G23: =G21+G22 -> 46592.945
A24: Parent opex, interest and tax | B24: 6984 | C24: =B24*(1+Assumptions!$B$100) -> 7403.04 | D24: =C24*(1+Assumptions!$B$100) -> 7847.2224 | E24: =D24*(1+Assumptions!$B$100) -> 8318.0557 | F24: =E24*(1+Assumptions!$B$100) -> 8817.1391 | G24: =F24*(1+Assumptions!$B$100) -> 9346.1674
A25: Equity deployment into strategic bets | B25: 15956 | C25: =Assumptions!B104 -> 20000 | D25: =Assumptions!C104 -> 24000 | E25: =Assumptions!D104 -> 26000 | F25: =Assumptions!E104 -> 27000 | G25: =Assumptions!F104 -> 28000
A26: Surplus / (deficit) | B26: =B23-B24-B25 -> 9588 | C26: =C23-C24-C25 -> 6323.6819 | D26: =D23-D24-D25 -> 2772.8423 | E26: =E23-E24-E25 -> 3385.1721 | F26: =F23-F24-F25 -> 6316.2144 | G26: =G23-G24-G25 -> 9246.778
A27: Cumulative net cash | B27: 21841 | C27: =B27+C26 -> 28164.682 | D27: =C27+D26 -> 30937.524 | E27: =D27+E26 -> 34322.696 | F27: =E27+F26 -> 40638.911 | G27: =F27+G26 -> 49885.689
A28: TCS as % of dividend inflow | B28: =B21/B23 -> 0.86974299 | C28: =C21/C23 -> 0.86306615 | D28: =D21/D23 -> 0.85459358 | E28: =E21/E23 -> 0.85446769 | F28: =F21/F23 -> 0.85804901 | G28: =G21/G23 -> 0.8600829
A29: Dividend cover of capital call (×) | B29: =B23/B25 -> 2.0386062 | C29: =C23/C25 -> 1.6863361 | D29: =D23/D25 -> 1.4425027 | E29: =E23/E25 -> 1.4501241 | F29: =F23/F25 -> 1.5604946 | G29: =G23/G25 -> 1.6640338
A31: Cumulative surplus / (deficit) FY27–FY31 | C31: =SUM(C26:G26) -> 28044.689
A34: Bear — Slow Bleed
B35: FY26A | C35: FY27 | D35: FY28 | E35: FY29 | F35: FY30 | G35: FY31
A36: Dividend from TCS | B36: 28291 | C36: ='Scenario Output'!C67 -> 27111.903 | D36: ='Scenario Output'!D67 -> 23599.262 | E36: ='Scenario Output'!E67 -> 22682.846 | F36: ='Scenario Output'!F67 -> 22952.588 | G36: ='Scenario Output'!G67 -> 23582.966
A37: Dividend from other listed holdings | B37: 4237 | C37: =B37*(1+Assumptions!$B$98) -> 4618.33 | D37: =C37*(1+Assumptions!$B$98) -> 5033.9797 | E37: =D37*(1+Assumptions!$B$98) -> 5487.0379 | F37: =E37*(1+Assumptions!$B$98) -> 5980.8713 | G37: =F37*(1+Assumptions!$B$98) -> 6519.1497
A38: Total dividend inflow | B38: =B36+B37 -> 32528 | C38: =C36+C37 -> 31730.233 | D38: =D36+D37 -> 28633.242 | E38: =E36+E37 -> 28169.884 | F38: =F36+F37 -> 28933.459 | G38: =G36+G37 -> 30102.116
A39: Parent opex, interest and tax | B39: 6984 | C39: =B39*(1+Assumptions!$B$100) -> 7403.04 | D39: =C39*(1+Assumptions!$B$100) -> 7847.2224 | E39: =D39*(1+Assumptions!$B$100) -> 8318.0557 | F39: =E39*(1+Assumptions!$B$100) -> 8817.1391 | G39: =F39*(1+Assumptions!$B$100) -> 9346.1674
A40: Equity deployment into strategic bets | B40: 15956 | C40: =Assumptions!B104 -> 20000 | D40: =Assumptions!C104 -> 24000 | E40: =Assumptions!D104 -> 26000 | F40: =Assumptions!E104 -> 27000 | G40: =Assumptions!F104 -> 28000
A41: Surplus / (deficit) | B41: =B38-B39-B40 -> 9588 | C41: =C38-C39-C40 -> 4327.1933 | D41: =D38-D39-D40 -> -3213.9807 | E41: =E38-E39-E40 -> -6148.1719 | F41: =F38-F39-F40 -> -6883.6798 | G41: =G38-G39-G40 -> -7244.0514
A42: Cumulative net cash | B42: 21841 | C42: =B42+C41 -> 26168.193 | D42: =C42+D41 -> 22954.213 | E42: =D42+E41 -> 16806.041 | F42: =E42+F41 -> 9922.3608 | G42: =F42+G41 -> 2678.3094
A43: TCS as % of dividend inflow | B43: =B36/B38 -> 0.86974299 | C43: =C36/C38 -> 0.85445017 | D43: =D36/D38 -> 0.82419107 | E43: =E36/E38 -> 0.80521617 | F43: =F36/F38 -> 0.79328876 | G43: =G36/G38 -> 0.78343218
A44: Dividend cover of capital call (×) | B44: =B38/B40 -> 2.0386062 | C44: =C38/C40 -> 1.5865117 | D44: =D38/D40 -> 1.1930517 | E44: =E38/E40 -> 1.0834571 | F44: =F38/F40 -> 1.0716096 | G44: =G38/G40 -> 1.0750756
A46: Cumulative surplus / (deficit) FY27–FY31 | C46: =SUM(C41:G41) -> -19162.691
A49: Severe — Structural Break
B50: FY26A | C50: FY27 | D50: FY28 | E50: FY29 | F50: FY30 | G50: FY31
...

Sheet Sensitivity
A1: Sensitivity — FY31 dividend to Tata Sons (₹ crore)
A2: Rows: FY26–FY31 revenue CAGR (constant currency). Columns: FY31 operating margin.
A4: Fixed inputs for this grid
A5: FY26 revenue ($mn) | B5: =Assumptions!B5 -> 30017
A6: FY31 ₹/US$ | B6: =Assumptions!B8*(1+Assumptions!B9)^5 -> 98.219028
A7: Free cash flow / net income | B7: 0.82
A8: Dividend as % of free cash flow | B8: 0.92
A10: FY31 dividend to Tata Sons (₹ crore)
A11: Revenue CAGR \ FY31 margin | B11: 0.175 | C11: 0.19 | D11: 0.205 | E11: 0.22 | F11: 0.235 | G11: 0.25 | H11: 0.265
A12: -0.09 | B12: =$B$5*(1+$A12)^5*(B$11+Assumptions!$B$10)*(1-Assumptions!$B$11)*$B$6/10*$B$7*$B$8*Assumptions!$B$12 -> 14168.458 | C12: =$B$5*(1+$A12)^5*(C$11+Assumptions!$B$10)*(1-Assumptions!$B$11)*$B$6/10*$B$7*$B$8*Assumptions!$B$12 -> 15281.164 | D12: =$B$5*(1+$A12)^5*(D$11+Assumptions!$B$10)*(1-Assumptions!$B$11)*$B$6/10*$B$7*$B$8*Assumptions!$B$12 -> 16393.87 | E12: =$B$5*(1+$A12)^5*(E$11+Assumptions!$B$10)*(1-Assumptions!$B$11)*$B$6/10*$B$7*$B$8*Assumptions!$B$12 -> 17506.576 | F12: =$B$5*(1+$A12)^5*(F$11+Assumptions!$B$10)*(1-Assumptions!$B$11)*$B$6/10*$B$7*$B$8*Assumptions!$B$12 -> 18619.282 | G12: =$B$5*(1+$A12)^5*(G$11+Assumptions!$B$10)*(1-Assumptions!$B$11)*$B$6/10*$B$7*$B$8*Assumptions!$B$12 -> 19731.988 | H12: =$B$5*(1+$A12)^5*(H$11+Assumptions!$B$10)*(1-Assumptions!$B$11)*$B$6/10*$B$7*$B$8*Assumptions!$B$12 -> 20844.694
A13: -0.06 | B13: =$B$5*(1+$A13)^5*(B$11+Assumptions!$B$10)*(1-Assumptions!$B$11)*$B$6/10*$B$7*$B$8*Assumptions!$B$12 -> 16663.065 | C13: =$B$5*(1+$A13)^5*(C$11+Assumptions!$B$10)*(1-Assumptions!$B$11)*$B$6/10*$B$7*$B$8*Assumptions!$B$12 -> 17971.682 | D13: =$B$5*(1+$A13)^5*(D$11+Assumptions!$B$10)*(1-Assumptions!$B$11)*$B$6/10*$B$7*$B$8*Assumptions!$B$12 -> 19280.3 | E13: =$B$5*(1+$A13)^5*(E$11+Assumptions!$B$10)*(1-Assumptions!$B$11)*$B$6/10*$B$7*$B$8*Assumptions!$B$12 -> 20588.918 | F13: =$B$5*(1+$A13)^5*(F$11+Assumptions!$B$10)*(1-Assumptions!$B$11)*$B$6/10*$B$7*$B$8*Assumptions!$B$12 -> 21897.535 | G13: =$B$5*(1+$A13)^5*(G$11+Assumptions!$B$10)*(1-Assumptions!$B$11)*$B$6/10*$B$7*$B$8*Assumptions!$B$12 -> 23206.153 | H13: =$B$5*(1+$A13)^5*(H$11+Assumptions!$B$10)*(1-Assumptions!$B$11)*$B$6/10*$B$7*$B$8*Assumptions!$B$12 -> 24514.77
A14: -0.03 | B14: =$B$5*(1+$A14)^5*(B$11+Assumptions!$B$10)*(1-Assumptions!$B$11)*$B$6/10*$B$7*$B$8*Assumptions!$B$12 -> 19497.291 | C14: =$B$5*(1+$A14)^5*(C$11+Assumptions!$B$10)*(1-Assumptions!$B$11)*$B$6/10*$B$7*$B$8*Assumptions!$B$12 -> 21028.492 | D14: =$B$5*(1+$A14)^5*(D$11+Assumptions!$B$10)*(1-Assumptions!$B$11)*$B$6/10*$B$7*$B$8*Assumptions!$B$12 -> 22559.693 | E14: =$B$5*(1+$A14)^5*(E$11+Assumptions!$B$10)*(1-Assumptions!$B$11)*$B$6/10*$B$7*$B$8*Assumptions!$B$12 -> 24090.894 | F14: =$B$5*(1+$A14)^5*(F$11+Assumptions!$B$10)*(1-Assumptions!$B$11)*$B$6/10*$B$7*$B$8*Assumptions!$B$12 -> 25622.095 | G14: =$B$5*(1+$A14)^5*(G$11+Assumptions!$B$10)*(1-Assumptions!$B$11)*$B$6/10*$B$7*$B$8*Assumptions!$B$12 -> 27153.296 | H14: =$B$5*(1+$A14)^5*(H$11+Assumptions!$B$10)*(1-Assumptions!$B$11)*$B$6/10*$B$7*$B$8*Assumptions!$B$12 -> 28684.497
A15: 0 | B15: =$B$5*(1+$A15)^5*(B$11+Assumptions!$B$10)*(1-Assumptions!$B$11)*$B$6/10*$B$7*$B$8*Assumptions!$B$12 -> 22704.692 | C15: =$B$5*(1+$A15)^5*(C$11+Assumptions!$B$10)*(1-Assumptions!$B$11)*$B$6/10*$B$7*$B$8*Assumptions!$B$12 -> 24487.783 | D15: =$B$5*(1+$A15)^5*(D$11+Assumptions!$B$10)*(1-Assumptions!$B$11)*$B$6/10*$B$7*$B$8*Assumptions!$B$12 -> 26270.874 | E15: =$B$5*(1+$A15)^5*(E$11+Assumptions!$B$10)*(1-Assumptions!$B$11)*$B$6/10*$B$7*$B$8*Assumptions!$B$12 -> 28053.965 | F15: =$B$5*(1+$A15)^5*(F$11+Assumptions!$B$10)*(1-Assumptions!$B$11)*$B$6/10*$B$7*$B$8*Assumptions!$B$12 -> 29837.056 | G15: =$B$5*(1+$A15)^5*(G$11+Assumptions!$B$10)*(1-Assumptions!$B$11)*$B$6/10*$B$7*$B$8*Assumptions!$B$12 -> 31620.147 | H15: =$B$5*(1+$A15)^5*(H$11+Assumptions!$B$10)*(1-Assumptions!$B$11)*$B$6/10*$B$7*$B$8*Assumptions!$B$12 -> 33403.238
A16: 0.02 | B16: =$B$5*(1+$A16)^5*(B$11+Assumptions!$B$10)*(1-Assumptions!$B$11)*$B$6/10*$B$7*$B$8*Assumptions!$B$12 -> 25067.814 | C16: =$B$5*(1+$A16)^5*(C$11+Assumptions!$B$10)*(1-Assumptions!$B$11)*$B$6/10*$B$7*$B$8*Assumptions!$B$12 -> 27036.491 | D16: =$B$5*(1+$A16)^5*(D$11+Assumptions!$B$10)*(1-Assumptions!$B$11)*$B$6/10*$B$7*$B$8*Assumptions!$B$12 -> 29005.167 | E16: =$B$5*(1+$A16)^5*(E$11+Assumptions!$B$10)*(1-Assumptions!$B$11)*$B$6/10*$B$7*$B$8*Assumptions!$B$12 -> 30973.844 | F16: =$B$5*(1+$A16)^5*(F$11+Assumptions!$B$10)*(1-Assumptions!$B$11)*$B$6/10*$B$7*$B$8*Assumptions!$B$12 -> 32942.52 | G16: =$B$5*(1+$A16)^5*(G$11+Assumptions!$B$10)*(1-Assumptions!$B$11)*$B$6/10*$B$7*$B$8*Assumptions!$B$12 -> 34911.197 | H16: =$B$5*(1+$A16)^5*(H$11+Assumptions!$B$10)*(1-Assumptions!$B$11)*$B$6/10*$B$7*$B$8*Assumptions!$B$12 -> 36879.873
A17: 0.04 | B17: =$B$5*(1+$A17)^5*(B$11+Assumptions!$B$10)*(1-Assumptions!$B$11)*$B$6/10*$B$7*$B$8*Assumptions!$B$12 -> 27623.729 | C17: =$B$5*(1+$A17)^5*(C$11+Assumptions!$B$10)*(1-Assumptions!$B$11)*$B$6/10*$B$7*$B$8*Assumptions!$B$12 -> 29793.132 | D17: =$B$5*(1+$A17)^5*(D$11+Assumptions!$B$10)*(1-Assumptions!$B$11)*$B$6/10*$B$7*$B$8*Assumptions!$B$12 -> 31962.535 | E17: =$B$5*(1+$A17)^5*(E$11+Assumptions!$B$10)*(1-Assumptions!$B$11)*$B$6/10*$B$7*$B$8*Assumptions!$B$12 -> 34131.938 | F17: =$B$5*(1+$A17)^5*(F$11+Assumptions!$B$10)*(1-Assumptions!$B$11)*$B$6/10*$B$7*$B$8*Assumptions!$B$12 -> 36301.34 | G17: =$B$5*(1+$A17)^5*(G$11+Assumptions!$B$10)*(1-Assumptions!$B$11)*$B$6/10*$B$7*$B$8*Assumptions!$B$12 -> 38470.743 | H17: =$B$5*(1+$A17)^5*(H$11+Assumptions!$B$10)*(1-Assumptions!$B$11)*$B$6/10*$B$7*$B$8*Assumptions!$B$12 -> 40640.146
A18: 0.06 | B18: =$B$5*(1+$A18)^5*(B$11+Assumptions!$B$10)*(1-Assumptions!$B$11)*$B$6/10*$B$7*$B$8*Assumptions!$B$12 -> 30383.999 | C18: =$B$5*(1+$A18)^5*(C$11+Assumptions!$B$10)*(1-Assumptions!$B$11)*$B$6/10*$B$7*$B$8*Assumptions!$B$12 -> 32770.177 | D18: =$B$5*(1+$A18)^5*(D$11+Assumptions!$B$10)*(1-Assumptions!$B$11)*$B$6/10*$B$7*$B$8*Assumptions!$B$12 -> 35156.355 | E18: =$B$5*(1+$A18)^5*(E$11+Assumptions!$B$10)*(1-Assumptions!$B$11)*$B$6/10*$B$7*$B$8*Assumptions!$B$12 -> 37542.533 | F18: =$B$5*(1+$A18)^5*(F$11+Assumptions!$B$10)*(1-Assumptions!$B$11)*$B$6/10*$B$7*$B$8*Assumptions!$B$12 -> 39928.711 | G18: =$B$5*(1+$A18)^5*(G$11+Assumptions!$B$10)*(1-Assumptions!$B$11)*$B$6/10*$B$7*$B$8*Assumptions!$B$12 -> 42314.889 | H18: =$B$5*(1+$A18)^5*(H$11+Assumptions!$B$10)*(1-Assumptions!$B$11)*$B$6/10*$B$7*$B$8*Assumptions!$B$12 -> 44701.067
A19: 0.08 | B19: =$B$5*(1+$A19)^5*(B$11+Assumptions!$B$10)*(1-Assumptions!$B$11)*$B$6/10*$B$7*$B$8*Assumptions!$B$12 -> 33360.641 | C19: =$B$5*(1+$A19)^5*(C$11+Assumptions!$B$10)*(1-Assumptions!$B$11)*$B$6/10*$B$7*$B$8*Assumptions!$B$12 -> 35980.587 | D19: =$B$5*(1+$A19)^5*(D$11+Assumptions!$B$10)*(1-Assumptions!$B$11)*$B$6/10*$B$7*$B$8*Assumptions!$B$12 -> 38600.532 | E19: =$B$5*(1+$A19)^5*(E$11+Assumptions!$B$10)*(1-Assumptions!$B$11)*$B$6/10*$B$7*$B$8*Assumptions!$B$12 -> 41220.478 | F19: =$B$5*(1+$A19)^5*(F$11+Assumptions!$B$10)*(1-Assumptions!$B$11)*$B$6/10*$B$7*$B$8*Assumptions!$B$12 -> 43840.424 | G19: =$B$5*(1+$A19)^5*(G$11+Assumptions!$B$10)*(1-Assumptions!$B$11)*$B$6/10*$B$7*$B$8*Assumptions!$B$12 -> 46460.369 | H19: =$B$5*(1+$A19)^5*(H$11+Assumptions!$B$10)*(1-Assumptions!$B$11)*$B$6/10*$B$7*$B$8*Assumptions!$B$12 -> 49080.315
A20: 0.1 | B20: =$B$5*(1+$A20)^5*(B$11+Assumptions!$B$10)*(1-Assumptions!$B$11)*$B$6/10*$B$7*$B$8*Assumptions!$B$12 -> 36566.133 | C20: =$B$5*(1+$A20)^5*(C$11+Assumptions!$B$10)*(1-Assumptions!$B$11)*$B$6/10*$B$7*$B$8*Assumptions!$B$12 -> 39437.819 | D20: =$B$5*(1+$A20)^5*(D$11+Assumptions!$B$10)*(1-Assumptions!$B$11)*$B$6/10*$B$7*$B$8*Assumptions!$B$12 -> 42309.505 | E20: =$B$5*(1+$A20)^5*(E$11+Assumptions!$B$10)*(1-Assumptions!$B$11)*$B$6/10*$B$7*$B$8*Assumptions!$B$12 -> 45181.191 | F20: =$B$5*(1+$A20)^5*(F$11+Assumptions!$B$10)*(1-Assumptions!$B$11)*$B$6/10*$B$7*$B$8*Assumptions!$B$12 -> 48052.877 | G20: =$B$5*(1+$A20)^5*(G$11+Assumptions!$B$10)*(1-Assumptions!$B$11)*$B$6/10*$B$7*$B$8*Assumptions!$B$12 -> 50924.562 | H20: =$B$5*(1+$A20)^5*(H$11+Assumptions!$B$10)*(1-Assumptions!$B$11)*$B$6/10*$B$7*$B$8*Assumptions!$B$12 -> 53796.248
A22: Reference: Tata Sons received ₹28,291 crore from TCS in FY26 and ₹32,184 crore in FY25. Cells below ~₹28,000 crore mean the parent's dividend income does not recover to FY26 levels by FY31.
A25: Break-even check
A26: FY31 capital call on Tata Sons (₹ crore) | B26: =Assumptions!F104 -> 28000
A27: Plus parent opex, interest and tax (₹ crore) | B27: =Assumptions!B99*(1+Assumptions!B100)^5 -> 9346.1674
A28: Less non-TCS dividend income (₹ crore) | B28: =-Assumptions!B97*(1+Assumptions!B98)^5 -> -6519.1497
A29: TCS dividend to Tata Sons needed to break even in FY31 | B29: =SUM(B26:B28) -> 30827.018

Sheet Risk Register
A1: Revenue at risk by exposure bucket
A2: Gross revenue at risk = FY26 revenue in the bucket × the share of its work AI can substantially automate by FY31. It is a measure of exposure, not of expected loss: what is actually lost depends on how much of the productivity gain is passed to the client and how far volume expands in response.
A4: Exposure bucket | B4: FY26 weight | C4: FY26 $mn | D4: Automatable share | E4: Gross rev at risk $mn | F4: Severe-case FY31 $mn | G4: Assessment
A5: Application Development & Maintenance (custom) | B5: =Assumptions!B17 -> 0.32 | C5: =Assumptions!C17 -> 9605.44 | D5: =Assumptions!D17 -> 0.55 | E5: =Assumptions!E17 -> 5282.992 | F5: ='Revenue Build'!G48 -> 4920.9778 | G5: Code generation, test automation and agentic L1/L2 support attack the core of this book. Largest single pool and the most exposed.
A6: Enterprise / Package Application Services | B6: =Assumptions!B18 -> 0.13 | C6: =Assumptions!C18 -> 3902.21 | D6: =Assumptions!D18 -> 0.4 | E6: =Assumptions!E18 -> 1560.884 | F6: ='Revenue Build'!G49 -> 2481.1232 | G6: SAP/Oracle/Salesforce migration and rollout. Config work automates; change management, data migration and integration hold value.
A7: Cloud & Infrastructure Managed Services | B7: =Assumptions!B19 -> 0.16 | C7: =Assumptions!C19 -> 4802.72 | D7: =Assumptions!D19 -> 0.5 | E7: =Assumptions!E19 -> 2401.36 | F7: ='Revenue Build'!G50 -> 2884.4593 | G7: AIOps compresses run-cost; offset by AI-infrastructure build, GPU estate operations and the HyperVault adjacency.
A8: Business Process Services | B8: =Assumptions!B20 -> 0.1 | C8: =Assumptions!C20 -> 3001.7 | D8: =Assumptions!D20 -> 0.65 | E8: =Assumptions!E20 -> 1951.105 | F8: ='Revenue Build'!G51 -> 1045.7089 | G8: Most directly substitutable. Agentic workflows displace seat-based delivery; the FTE pricing model is the liability.
A9: Engineering & R&D Services | B9: =Assumptions!B21 -> 0.09 | C9: =Assumptions!C21 -> 2701.53 | D9: =Assumptions!D21 -> 0.25 | E9: =Assumptions!E21 -> 675.3825 | F9: ='Revenue Build'!G52 -> 2109.6361 | G9: Embedded, semiconductor, automotive software. Least substitutable near-term and structurally growing.
A10: Consulting, Data, AI & Cybersecurity | B10: =Assumptions!B22 -> 0.15 | C10: =Assumptions!C22 -> 4502.55 | D10: =Assumptions!D22 -> 0.15 | E10: =Assumptions!E22 -> 675.3825 | F10: ='Revenue Build'!G53 -> 3854.0231 | G10: The growth engine. AI-native demand, data estate rebuild, model governance, security. TCS AI book already ~8.5% of revenue.
A11: Products & Platforms (BaNCS, ignio, iON, ADD) | B11: =Assumptions!B23 -> 0.05 | C11: =Assumptions!C23 -> 1500.85 | D11: =Assumptions!D23 -> 0.1 | E11: =Assumptions!E23 -> 150.085 | F11: ='Revenue Build'!G54 -> 1213.4636 | G11: IP-led, non-linear. AI raises product value rather than deflating it. Strategically under-scaled at ~5% of revenue.
A12: Total | B12: =SUM(B5:B11) -> 1 | C12: =SUM(C5:C11) -> 30017 | E12: =SUM(E5:E11) -> 12697.191 | F12: =SUM(F5:F11) -> 18509.392
A14: Gross revenue at risk as % of FY26 revenue | C14: =E12/C12 -> 0.423
